<?xml version="1.0" encoding="UTF-8"?>
<!-- Generated by org.testng.reporters.JUnitReportReporter -->
<testsuite hostname="TR-JDGMXY2" failures="3" tests="4" name="com.trgr.quality.maf.tests.LoginTest" time="59.189" errors="1" timestamp="2021-02-23T13:50:02 ART" skipped="0">
  <testcase classname="com.trgr.quality.maf.tests.LoginTest" name="driverclose" time="4.322">
    <error message="chrome not reachable
  (Session info: chrome=88.0.4324.182)
Build info: version: &#039;3.141.59&#039;, revision: &#039;e82be7d358&#039;, time: &#039;2018-11-14T08:17:03&#039;
System info: host: &#039;TR-JDGMXY2&#039;, ip: &#039;192.168.19.184&#039;, os.name: &#039;Windows 10&#039;, os.arch: &#039;amd64&#039;, os.version: &#039;10.0&#039;, java.version: &#039;14.0.2&#039;
Driver info: org.openqa.selenium.chrome.ChromeDriver
Capabilities {acceptInsecureCerts: false, browserName: chrome, browserVersion: 88.0.4324.182, chrome: {chromedriverVersion: 88.0.4324.96 (68dba2d8a0b14..., userDataDir: C:\Users\C275973\AppData\Lo...}, goog:chromeOptions: {debuggerAddress: localhost:52050}, javascriptEnabled: true, networkConnectionEnabled: false, pageLoadStrategy: normal, platform: WINDOWS, platformName: WINDOWS, proxy: Proxy(), setWindowRect: true, strictFileInteractability: false, timeouts: {implicit: 0, pageLoad: 300000, script: 30000}, unhandledPromptBehavior: dismiss and notify, webauthn:extension:largeBlob: true, webauthn:virtualAuthenticators: true}
Session ID: 1ffae3857eb65c15ba0d0e6aa0198241" type="org.openqa.selenium.WebDriverException">
      <![CDATA[org.openqa.selenium.WebDriverException: chrome not reachable
  (Session info: chrome=88.0.4324.182)
Build info: version: '3.141.59', revision: 'e82be7d358', time: '2018-11-14T08:17:03'
System info: host: 'TR-JDGMXY2', ip: '192.168.19.184', os.name: 'Windows 10', os.arch: 'amd64', os.version: '10.0', java.version: '14.0.2'
Driver info: org.openqa.selenium.chrome.ChromeDriver
Capabilities {acceptInsecureCerts: false, browserName: chrome, browserVersion: 88.0.4324.182, chrome: {chromedriverVersion: 88.0.4324.96 (68dba2d8a0b14..., userDataDir: C:\Users\C275973\AppData\Lo...}, goog:chromeOptions: {debuggerAddress: localhost:52050}, javascriptEnabled: true, networkConnectionEnabled: false, pageLoadStrategy: normal, platform: WINDOWS, platformName: WINDOWS, proxy: Proxy(), setWindowRect: true, strictFileInteractability: false, timeouts: {implicit: 0, pageLoad: 300000, script: 30000}, unhandledPromptBehavior: dismiss and notify, webauthn:extension:largeBlob: true, webauthn:virtualAuthenticators: true}
Session ID: 1ffae3857eb65c15ba0d0e6aa0198241
at java.base/jdk.internal.reflect.NativeConstructorAccessorImpl.newInstance0(Native Method)
at java.base/jdk.internal.reflect.NativeConstructorAccessorImpl.newInstance(NativeConstructorAccessorImpl.java:62)
at java.base/jdk.internal.reflect.DelegatingConstructorAccessorImpl.newInstance(DelegatingConstructorAccessorImpl.java:45)
at java.base/java.lang.reflect.Constructor.newInstanceWithCaller(Constructor.java:500)
at java.base/java.lang.reflect.Constructor.newInstance(Constructor.java:481)
at org.openqa.selenium.remote.http.W3CHttpResponseCodec.createException(W3CHttpResponseCodec.java:187)
at org.openqa.selenium.remote.http.W3CHttpResponseCodec.decode(W3CHttpResponseCodec.java:122)
at org.openqa.selenium.remote.http.W3CHttpResponseCodec.decode(W3CHttpResponseCodec.java:49)
at org.openqa.selenium.remote.HttpCommandExecutor.execute(HttpCommandExecutor.java:158)
at org.openqa.selenium.remote.service.DriverCommandExecutor.execute(DriverCommandExecutor.java:83)
at org.openqa.selenium.remote.RemoteWebDriver.execute(RemoteWebDriver.java:552)
at org.openqa.selenium.remote.RemoteWebDriver.execute(RemoteWebDriver.java:609)
at org.openqa.selenium.remote.RemoteWebDriver.close(RemoteWebDriver.java:442)
at com.trgr.quality.maf.webdriver.WebDriverFactory.removedriver(WebDriverFactory.java:175)
at com.trgr.quality.maf.basetest.BaseTest.driverclose(BaseTest.java:663)
at java.base/jdk.internal.reflect.NativeMethodAccessorImpl.invoke0(Native Method)
at java.base/jdk.internal.reflect.NativeMethodAccessorImpl.invoke(NativeMethodAccessorImpl.java:62)
at java.base/jdk.internal.reflect.DelegatingMethodAccessorImpl.invoke(DelegatingMethodAccessorImpl.java:43)
at java.base/java.lang.reflect.Method.invoke(Method.java:564)
at org.testng.internal.MethodInvocationHelper.invokeMethod(MethodInvocationHelper.java:132)
at org.testng.internal.MethodInvocationHelper.invokeMethodConsideringTimeout(MethodInvocationHelper.java:61)
at org.testng.internal.ConfigInvoker.invokeConfigurationMethod(ConfigInvoker.java:366)
at org.testng.internal.ConfigInvoker.invokeConfigurations(ConfigInvoker.java:320)
at org.testng.SuiteRunner.privateRun(SuiteRunner.java:351)
at org.testng.SuiteRunner.run(SuiteRunner.java:286)
at org.testng.SuiteRunnerWorker.runSuite(SuiteRunnerWorker.java:53)
at org.testng.SuiteRunnerWorker.run(SuiteRunnerWorker.java:96)
at org.testng.TestNG.runSuitesSequentially(TestNG.java:1218)
at org.testng.TestNG.runSuitesLocally(TestNG.java:1140)
at org.testng.TestNG.runSuites(TestNG.java:1069)
at org.testng.TestNG.run(TestNG.java:1037)
at org.testng.remote.AbstractRemoteTestNG.run(AbstractRemoteTestNG.java:115)
at org.testng.remote.RemoteTestNG.initAndRun(RemoteTestNG.java:251)
at org.testng.remote.RemoteTestNG.main(RemoteTestNG.java:77)
]]>
    </error>
  </testcase> <!-- driverclose -->
  <system-out/>
  <testcase classname="com.trgr.quality.maf.tests.LoginTest" name="loginWithValidAndInvalidCredentials" time="54.822">
    <failure message="The following asserts failed:
	MAFQABANG-32:Login with valid and invalid credentails : Validated Login with invalid username expected [true] but found [false],
	MAFQABANG-32:Login with valid and invalid credentails : Validated Login with invalid password expected [true] but found [false],
	Exception in Test expected [true] but found [false]" type="java.lang.AssertionError">
      <![CDATA[java.lang.AssertionError: The following asserts failed:
MAFQABANG-32:Login with valid and invalid credentails : Validated Login with invalid username expected [true] but found [false],
MAFQABANG-32:Login with valid and invalid credentails : Validated Login with invalid password expected [true] but found [false],
Exception in Test expected [true] but found [false]
at org.testng.asserts.SoftAssert.assertAll(SoftAssert.java:47)
at org.testng.asserts.SoftAssert.assertAll(SoftAssert.java:31)
at com.trgr.quality.maf.tests.LoginTest.loginWithValidAndInvalidCredentials(LoginTest.java:123)
at java.base/jdk.internal.reflect.NativeMethodAccessorImpl.invoke0(Native Method)
at java.base/jdk.internal.reflect.NativeMethodAccessorImpl.invoke(NativeMethodAccessorImpl.java:62)
at java.base/jdk.internal.reflect.DelegatingMethodAccessorImpl.invoke(DelegatingMethodAccessorImpl.java:43)
at java.base/java.lang.reflect.Method.invoke(Method.java:564)
at org.testng.internal.MethodInvocationHelper.invokeMethod(MethodInvocationHelper.java:132)
at org.testng.internal.TestInvoker.invokeMethod(TestInvoker.java:599)
at org.testng.internal.TestInvoker.invokeTestMethod(TestInvoker.java:174)
at org.testng.internal.MethodRunner.runInSequence(MethodRunner.java:46)
at org.testng.internal.TestInvoker$MethodInvocationAgent.invoke(TestInvoker.java:822)
at org.testng.internal.TestInvoker.invokeTestMethods(TestInvoker.java:147)
at org.testng.internal.TestMethodWorker.invokeTestMethods(TestMethodWorker.java:146)
at org.testng.internal.TestMethodWorker.run(TestMethodWorker.java:128)
at java.base/java.util.ArrayList.forEach(ArrayList.java:1511)
at org.testng.TestRunner.privateRun(TestRunner.java:764)
at org.testng.TestRunner.run(TestRunner.java:585)
at org.testng.SuiteRunner.runTest(SuiteRunner.java:384)
at org.testng.SuiteRunner.runSequentially(SuiteRunner.java:378)
at org.testng.SuiteRunner.privateRun(SuiteRunner.java:337)
at org.testng.SuiteRunner.run(SuiteRunner.java:286)
at org.testng.SuiteRunnerWorker.runSuite(SuiteRunnerWorker.java:53)
at org.testng.SuiteRunnerWorker.run(SuiteRunnerWorker.java:96)
at org.testng.TestNG.runSuitesSequentially(TestNG.java:1218)
at org.testng.TestNG.runSuitesLocally(TestNG.java:1140)
at org.testng.TestNG.runSuites(TestNG.java:1069)
at org.testng.TestNG.run(TestNG.java:1037)
at org.testng.remote.AbstractRemoteTestNG.run(AbstractRemoteTestNG.java:115)
at org.testng.remote.RemoteTestNG.initAndRun(RemoteTestNG.java:251)
at org.testng.remote.RemoteTestNG.main(RemoteTestNG.java:77)
]]>
    </failure>
  </testcase> <!-- loginWithValidAndInvalidCredentials -->
  <system-out/>
  <testcase classname="com.trgr.quality.maf.tests.LoginTest" name="loginUsingSaveUserNameAndPwd" time="0.025">
    <failure message="The following asserts failed:
	Exception in Test expected [true] but found [false]" type="java.lang.AssertionError">
      <![CDATA[java.lang.AssertionError: The following asserts failed:
Exception in Test expected [true] but found [false]
at org.testng.asserts.SoftAssert.assertAll(SoftAssert.java:47)
at org.testng.asserts.SoftAssert.assertAll(SoftAssert.java:31)
at com.trgr.quality.maf.tests.LoginTest.loginUsingSaveUserNameAndPwd(LoginTest.java:218)
at java.base/jdk.internal.reflect.NativeMethodAccessorImpl.invoke0(Native Method)
at java.base/jdk.internal.reflect.NativeMethodAccessorImpl.invoke(NativeMethodAccessorImpl.java:62)
at java.base/jdk.internal.reflect.DelegatingMethodAccessorImpl.invoke(DelegatingMethodAccessorImpl.java:43)
at java.base/java.lang.reflect.Method.invoke(Method.java:564)
at org.testng.internal.MethodInvocationHelper.invokeMethod(MethodInvocationHelper.java:132)
at org.testng.internal.TestInvoker.invokeMethod(TestInvoker.java:599)
at org.testng.internal.TestInvoker.invokeTestMethod(TestInvoker.java:174)
at org.testng.internal.MethodRunner.runInSequence(MethodRunner.java:46)
at org.testng.internal.TestInvoker$MethodInvocationAgent.invoke(TestInvoker.java:822)
at org.testng.internal.TestInvoker.invokeTestMethods(TestInvoker.java:147)
at org.testng.internal.TestMethodWorker.invokeTestMethods(TestMethodWorker.java:146)
at org.testng.internal.TestMethodWorker.run(TestMethodWorker.java:128)
at java.base/java.util.ArrayList.forEach(ArrayList.java:1511)
at org.testng.TestRunner.privateRun(TestRunner.java:764)
at org.testng.TestRunner.run(TestRunner.java:585)
at org.testng.SuiteRunner.runTest(SuiteRunner.java:384)
at org.testng.SuiteRunner.runSequentially(SuiteRunner.java:378)
at org.testng.SuiteRunner.privateRun(SuiteRunner.java:337)
at org.testng.SuiteRunner.run(SuiteRunner.java:286)
at org.testng.SuiteRunnerWorker.runSuite(SuiteRunnerWorker.java:53)
at org.testng.SuiteRunnerWorker.run(SuiteRunnerWorker.java:96)
at org.testng.TestNG.runSuitesSequentially(TestNG.java:1218)
at org.testng.TestNG.runSuitesLocally(TestNG.java:1140)
at org.testng.TestNG.runSuites(TestNG.java:1069)
at org.testng.TestNG.run(TestNG.java:1037)
at org.testng.remote.AbstractRemoteTestNG.run(AbstractRemoteTestNG.java:115)
at org.testng.remote.RemoteTestNG.initAndRun(RemoteTestNG.java:251)
at org.testng.remote.RemoteTestNG.main(RemoteTestNG.java:77)
]]>
    </failure>
  </testcase> <!-- loginUsingSaveUserNameAndPwd -->
  <system-out/>
  <testcase classname="com.trgr.quality.maf.tests.LoginTest" name="loginUsingSaveUserName" time="0.020">
    <failure message="The following asserts failed:
	Exception in Test expected [true] but found [false]" type="java.lang.AssertionError">
      <![CDATA[java.lang.AssertionError: The following asserts failed:
Exception in Test expected [true] but found [false]
at org.testng.asserts.SoftAssert.assertAll(SoftAssert.java:47)
at org.testng.asserts.SoftAssert.assertAll(SoftAssert.java:31)
at com.trgr.quality.maf.tests.LoginTest.loginUsingSaveUserName(LoginTest.java:432)
at java.base/jdk.internal.reflect.NativeMethodAccessorImpl.invoke0(Native Method)
at java.base/jdk.internal.reflect.NativeMethodAccessorImpl.invoke(NativeMethodAccessorImpl.java:62)
at java.base/jdk.internal.reflect.DelegatingMethodAccessorImpl.invoke(DelegatingMethodAccessorImpl.java:43)
at java.base/java.lang.reflect.Method.invoke(Method.java:564)
at org.testng.internal.MethodInvocationHelper.invokeMethod(MethodInvocationHelper.java:132)
at org.testng.internal.TestInvoker.invokeMethod(TestInvoker.java:599)
at org.testng.internal.TestInvoker.invokeTestMethod(TestInvoker.java:174)
at org.testng.internal.MethodRunner.runInSequence(MethodRunner.java:46)
at org.testng.internal.TestInvoker$MethodInvocationAgent.invoke(TestInvoker.java:822)
at org.testng.internal.TestInvoker.invokeTestMethods(TestInvoker.java:147)
at org.testng.internal.TestMethodWorker.invokeTestMethods(TestMethodWorker.java:146)
at org.testng.internal.TestMethodWorker.run(TestMethodWorker.java:128)
at java.base/java.util.ArrayList.forEach(ArrayList.java:1511)
at org.testng.TestRunner.privateRun(TestRunner.java:764)
at org.testng.TestRunner.run(TestRunner.java:585)
at org.testng.SuiteRunner.runTest(SuiteRunner.java:384)
at org.testng.SuiteRunner.runSequentially(SuiteRunner.java:378)
at org.testng.SuiteRunner.privateRun(SuiteRunner.java:337)
at org.testng.SuiteRunner.run(SuiteRunner.java:286)
at org.testng.SuiteRunnerWorker.runSuite(SuiteRunnerWorker.java:53)
at org.testng.SuiteRunnerWorker.run(SuiteRunnerWorker.java:96)
at org.testng.TestNG.runSuitesSequentially(TestNG.java:1218)
at org.testng.TestNG.runSuitesLocally(TestNG.java:1140)
at org.testng.TestNG.runSuites(TestNG.java:1069)
at org.testng.TestNG.run(TestNG.java:1037)
at org.testng.remote.AbstractRemoteTestNG.run(AbstractRemoteTestNG.java:115)
at org.testng.remote.RemoteTestNG.initAndRun(RemoteTestNG.java:251)
at org.testng.remote.RemoteTestNG.main(RemoteTestNG.java:77)
]]>
    </failure>
  </testcase> <!-- loginUsingSaveUserName -->
  <system-out/>
</testsuite> <!-- com.trgr.quality.maf.tests.LoginTest -->
